Starting python http server... python -m http.serverStarting python http server... python -m http.serverTraceback (most recent call last):
  File "/home/pras/.asdf/installs/python/3.9.6/lib/python3.9/runpy.py", line 197, in _run_module_as_main
    return _run_code(code, main_globals, None,
  File "/home/pras/.asdf/installs/python/3.9.6/lib/python3.9/runpy.py", line 87, in _run_code
    exec(code, run_globals)
  File "/home/pras/.asdf/installs/python/3.9.6/lib/python3.9/http/server.py", line 1290, in <module>
    test(
  File "/home/pras/.asdf/installs/python/3.9.6/lib/python3.9/http/server.py", line 1245, in test
    with ServerClass(addr, HandlerClass) as httpd:
  File "/home/pras/.asdf/installs/python/3.9.6/lib/python3.9/socketserver.py", line 452, in __init__
    self.server_bind()
  File "/home/pras/.asdf/installs/python/3.9.6/lib/python3.9/http/server.py", line 1288, in server_bind
    return super().server_bind()
  File "/home/pras/.asdf/installs/python/3.9.6/lib/python3.9/http/server.py", line 138, in server_bind
    socketserver.TCPServer.server_bind(self)
  File "/home/pras/.asdf/installs/python/3.9.6/lib/python3.9/socketserver.py", line 466, in server_bind
    self.socket.bind(self.server_address)
OSError: [Errno 98] Address already in use
Traceback (most recent call last):
  File "/home/pras/.asdf/installs/python/3.9.6/lib/python3.9/runpy.py", line 197, in _run_module_as_main
    return _run_code(code, main_globals, None,
  File "/home/pras/.asdf/installs/python/3.9.6/lib/python3.9/runpy.py", line 87, in _run_code
    exec(code, run_globals)
  File "/home/pras/.asdf/installs/python/3.9.6/lib/python3.9/http/server.py", line 1290, in <module>
    test(
  File "/home/pras/.asdf/installs/python/3.9.6/lib/python3.9/http/server.py", line 1245, in test
    with ServerClass(addr, HandlerClass) as httpd:
  File "/home/pras/.asdf/installs/python/3.9.6/lib/python3.9/socketserver.py", line 452, in __init__
    self.server_bind()
  File "/home/pras/.asdf/installs/python/3.9.6/lib/python3.9/http/server.py", line 1288, in server_bind
    return super().server_bind()
  File "/home/pras/.asdf/installs/python/3.9.6/lib/python3.9/http/server.py", line 138, in server_bind
    socketserver.TCPServer.server_bind(self)
  File "/home/pras/.asdf/installs/python/3.9.6/lib/python3.9/socketserver.py", line 466, in server_bind
    self.socket.bind(self.server_address)
OSError: [Errno 98] Address already in use
Traceback (most recent call last):
  File "/home/pras/.asdf/installs/python/3.9.6/lib/python3.9/runpy.py", line 197, in _run_module_as_main
    return _run_code(code, main_globals, None,
  File "/home/pras/.asdf/installs/python/3.9.6/lib/python3.9/runpy.py", line 87, in _run_code
    exec(code, run_globals)
  File "/home/pras/.asdf/installs/python/3.9.6/lib/python3.9/http/server.py", line 1290, in <module>
    test(
  File "/home/pras/.asdf/installs/python/3.9.6/lib/python3.9/http/server.py", line 1245, in test
    with ServerClass(addr, HandlerClass) as httpd:
  File "/home/pras/.asdf/installs/python/3.9.6/lib/python3.9/socketserver.py", line 452, in __init__
    self.server_bind()
  File "/home/pras/.asdf/installs/python/3.9.6/lib/python3.9/http/server.py", line 1288, in server_bind
    return super().server_bind()
  File "/home/pras/.asdf/installs/python/3.9.6/lib/python3.9/http/server.py", line 138, in server_bind
    socketserver.TCPServer.server_bind(self)
  File "/home/pras/.asdf/installs/python/3.9.6/lib/python3.9/socketserver.py", line 466, in server_bind
    self.socket.bind(self.server_address)
OSError: [Errno 98] Address already in use
Traceback (most recent call last):
  File "/home/pras/.asdf/installs/python/3.9.6/lib/python3.9/runpy.py", line 197, in _run_module_as_main
    return _run_code(code, main_globals, None,
  File "/home/pras/.asdf/installs/python/3.9.6/lib/python3.9/runpy.py", line 87, in _run_code
    exec(code, run_globals)
  File "/home/pras/.asdf/installs/python/3.9.6/lib/python3.9/http/server.py", line 1290, in <module>
    test(
  File "/home/pras/.asdf/installs/python/3.9.6/lib/python3.9/http/server.py", line 1245, in test
    with ServerClass(addr, HandlerClass) as httpd:
  File "/home/pras/.asdf/installs/python/3.9.6/lib/python3.9/socketserver.py", line 452, in __init__
    self.server_bind()
  File "/home/pras/.asdf/installs/python/3.9.6/lib/python3.9/http/server.py", line 1288, in server_bind
    return super().server_bind()
  File "/home/pras/.asdf/installs/python/3.9.6/lib/python3.9/http/server.py", line 138, in server_bind
    socketserver.TCPServer.server_bind(self)
  File "/home/pras/.asdf/installs/python/3.9.6/lib/python3.9/socketserver.py", line 466, in server_bind
    self.socket.bind(self.server_address)
OSError: [Errno 98] Address already in use
Traceback (most recent call last):
  File "/home/pras/.asdf/installs/python/3.9.6/lib/python3.9/runpy.py", line 197, in _run_module_as_main
    return _run_code(code, main_globals, None,
  File "/home/pras/.asdf/installs/python/3.9.6/lib/python3.9/runpy.py", line 87, in _run_code
    exec(code, run_globals)
  File "/home/pras/.asdf/installs/python/3.9.6/lib/python3.9/http/server.py", line 1290, in <module>
    test(
  File "/home/pras/.asdf/installs/python/3.9.6/lib/python3.9/http/server.py", line 1245, in test
    with ServerClass(addr, HandlerClass) as httpd:
  File "/home/pras/.asdf/installs/python/3.9.6/lib/python3.9/socketserver.py", line 452, in __init__
    self.server_bind()
  File "/home/pras/.asdf/installs/python/3.9.6/lib/python3.9/http/server.py", line 1288, in server_bind
    return super().server_bind()
  File "/home/pras/.asdf/installs/python/3.9.6/lib/python3.9/http/server.py", line 138, in server_bind
    socketserver.TCPServer.server_bind(self)
  File "/home/pras/.asdf/installs/python/3.9.6/lib/python3.9/socketserver.py", line 466, in server_bind
    self.socket.bind(self.server_address)
OSError: [Errno 98] Address already in use
Traceback (most recent call last):
  File "/home/pras/.asdf/installs/python/3.9.6/lib/python3.9/runpy.py", line 197, in _run_module_as_main
    return _run_code(code, main_globals, None,
  File "/home/pras/.asdf/installs/python/3.9.6/lib/python3.9/runpy.py", line 87, in _run_code
    exec(code, run_globals)
  File "/home/pras/.asdf/installs/python/3.9.6/lib/python3.9/http/server.py", line 1290, in <module>
    test(
  File "/home/pras/.asdf/installs/python/3.9.6/lib/python3.9/http/server.py", line 1245, in test
    with ServerClass(addr, HandlerClass) as httpd:
  File "/home/pras/.asdf/installs/python/3.9.6/lib/python3.9/socketserver.py", line 452, in __init__
    self.server_bind()
  File "/home/pras/.asdf/installs/python/3.9.6/lib/python3.9/http/server.py", line 1288, in server_bind
    return super().server_bind()
  File "/home/pras/.asdf/installs/python/3.9.6/lib/python3.9/http/server.py", line 138, in server_bind
    socketserver.TCPServer.server_bind(self)
  File "/home/pras/.asdf/installs/python/3.9.6/lib/python3.9/socketserver.py", line 466, in server_bind
    self.socket.bind(self.server_address)
OSError: [Errno 98] Address already in use
Traceback (most recent call last):
  File "/home/pras/.asdf/installs/python/3.9.6/lib/python3.9/runpy.py", line 197, in _run_module_as_main
    return _run_code(code, main_globals, None,
  File "/home/pras/.asdf/installs/python/3.9.6/lib/python3.9/runpy.py", line 87, in _run_code
    exec(code, run_globals)
  File "/home/pras/.asdf/installs/python/3.9.6/lib/python3.9/http/server.py", line 1290, in <module>
    test(
  File "/home/pras/.asdf/installs/python/3.9.6/lib/python3.9/http/server.py", line 1245, in test
    with ServerClass(addr, HandlerClass) as httpd:
  File "/home/pras/.asdf/installs/python/3.9.6/lib/python3.9/socketserver.py", line 452, in __init__
    self.server_bind()
  File "/home/pras/.asdf/installs/python/3.9.6/lib/python3.9/http/server.py", line 1288, in server_bind
    return super().server_bind()
  File "/home/pras/.asdf/installs/python/3.9.6/lib/python3.9/http/server.py", line 138, in server_bind
    socketserver.TCPServer.server_bind(self)
  File "/home/pras/.asdf/installs/python/3.9.6/lib/python3.9/socketserver.py", line 466, in server_bind
    self.socket.bind(self.server_address)
OSError: [Errno 98] Address already in use
Traceback (most recent call last):
  File "/home/pras/.asdf/installs/python/3.9.6/lib/python3.9/runpy.py", line 197, in _run_module_as_main
    return _run_code(code, main_globals, None,
  File "/home/pras/.asdf/installs/python/3.9.6/lib/python3.9/runpy.py", line 87, in _run_code
    exec(code, run_globals)
  File "/home/pras/.asdf/installs/python/3.9.6/lib/python3.9/http/server.py", line 1290, in <module>
    test(
  File "/home/pras/.asdf/installs/python/3.9.6/lib/python3.9/http/server.py", line 1245, in test
    with ServerClass(addr, HandlerClass) as httpd:
  File "/home/pras/.asdf/installs/python/3.9.6/lib/python3.9/socketserver.py", line 452, in __init__
    self.server_bind()
  File "/home/pras/.asdf/installs/python/3.9.6/lib/python3.9/http/server.py", line 1288, in server_bind
    return super().server_bind()
  File "/home/pras/.asdf/installs/python/3.9.6/lib/python3.9/http/server.py", line 138, in server_bind
    socketserver.TCPServer.server_bind(self)
  File "/home/pras/.asdf/installs/python/3.9.6/lib/python3.9/socketserver.py", line 466, in server_bind
    self.socket.bind(self.server_address)
OSError: [Errno 98] Address already in use
Traceback (most recent call last):
  File "/home/pras/.asdf/installs/python/3.9.6/lib/python3.9/runpy.py", line 197, in _run_module_as_main
    return _run_code(code, main_globals, None,
  File "/home/pras/.asdf/installs/python/3.9.6/lib/python3.9/runpy.py", line 87, in _run_code
    exec(code, run_globals)
  File "/home/pras/.asdf/installs/python/3.9.6/lib/python3.9/http/server.py", line 1290, in <module>
    test(
  File "/home/pras/.asdf/installs/python/3.9.6/lib/python3.9/http/server.py", line 1245, in test
    with ServerClass(addr, HandlerClass) as httpd:
  File "/home/pras/.asdf/installs/python/3.9.6/lib/python3.9/socketserver.py", line 452, in __init__
    self.server_bind()
  File "/home/pras/.asdf/installs/python/3.9.6/lib/python3.9/http/server.py", line 1288, in server_bind
    return super().server_bind()
  File "/home/pras/.asdf/installs/python/3.9.6/lib/python3.9/http/server.py", line 138, in server_bind
    socketserver.TCPServer.server_bind(self)
  File "/home/pras/.asdf/installs/python/3.9.6/lib/python3.9/socketserver.py", line 466, in server_bind
    self.socket.bind(self.server_address)
OSError: [Errno 98] Address already in use
